nlibs/lib/python3.11/site-packages (from pymongo==4.6.1->-r requirements.txt (line 3)) (2.8.0)
Requirement already satisfied: anyio in ./.pythonlibs/lib/python3.11/site-packages (from httpx~=0.25.2->python-telegram-bot==20.7->-r requirements.txt (line 2)) (4.10.0)
Requirement already satisfied: certifi in ./.pythonlibs/lib/python3.11/site-packages (from httpx~=0.25.2->python-telegram-bot==20.7->-r requirements.txt (line 2)) (2025.8.3)
Requirement already satisfied: httpcore==1.* in ./.pythonlibs/lib/python3.11/site-packages (from httpx~=0.25.2->python-telegram-bot==20.7->-r requirements.txt (line 2)) (1.0.9)
Requirement already satisfied: idna in ./.pythonlibs/lib/python3.11/site-packages (from httpx~=0.25.2->python-telegram-bot==20.7->-r requirements.txt (line 2)) (3.10)
Requirement already satisfied: sniffio in ./.pythonlibs/lib/python3.11/site-packages (from httpx~=0.25.2->python-telegram-bot==20.7->-r requirements.txt (line 2)) (1.3.1)
Requirement already satisfied: h11>=0.16 in ./.pythonlibs/lib/python3.11/site-packages (from httpcore==1.*->httpx~=0.25.2->python-telegram-bot==20.7->-r requirements.txt (line 2)) (0.16.0)
Requirement already satisfied: typing_extensions>=4.5 in ./.pythonlibs/lib/python3.11/site-packages (from anyio->httpx~=0.25.2->python-telegram-bot==20.7->-r requirements.txt (line 2)) (4.15.0)
2025-09-16 11:37:23,995 - __main__ - INFO - Connected to MongoDB successfully
2025-09-16 11:37:24,010 - __main__ - INFO - Bot started successfully!
2025-09-16 11:37:24,579 - httpx - INFO - HTTP Request: POST https://api.telegram.org/bot8025028159:AAGcBBSs46xwjxEwEU3hYWZx-xE98tUXd0c/getMe "HTTP/1.1 200 OK"
2025-09-16 11:37:24,766 - httpx - INFO - HTTP Request: POST https://api.telegram.org/bot8025028159:AAGcBBSs46xwjxEwEU3hYWZx-xE98tUXd0c/deleteWebhook "HTTP/1.1 200 OK"
2025-09-16 11:37:24,768 - telegram.ext.Application - INFO - Application started
2025-09-16 11:37:29,515 - httpx - INFO - HTTP Request: POST https://api.telegram.org/bot8025028159:AAGcBBSs46xwjxEwEU3hYWZx-xE98tUXd0c/getUpdates "HTTP/1.1 409 Conflict"
2025-09-16 11:37:29,516 - telegram.ext.Updater - ERROR - Error while getting Updates: Conflict: terminated by other getUpdates request; make sure that only one bot instance is running
2025-09-16 11:37:29,516 - telegram.ext.Application - ERROR - No error handlers are registered, logging exception.
Traceback (most recent call last):
  File "/home/runner/workspace/.pythonlibs/lib/python3.11/site-packages/telegram/ext/_updater.py", line 688, in _network_loop_retry
    if not await action_cb():
           ^^^^^^^^^^^^^^^^^
  File "/home/runner/workspace/.pythonlibs/lib/python3.11/site-packages/telegram/ext/_updater.py", line 384, in polling_action_cb
    raise exc
  File "/home/runner/workspace/.pythonlibs/lib/python3.11/site-packages/telegram/ext/_updater.py", line 373, in polling_action_cb
    updates = await self.bot.get_updates(
              ^^^^^^^^^^^^^^^^^^^^^^^^^^^
  File "/home/runner/workspace/.pythonlibs/lib/python3.11/site-packages/telegram/ext/_extbot.py", line 558, in get_updates
    updates = await super().get_updates(
              ^^^^^^^^^^^^^^^^^^^^^^^^^^
  File "/home/runner/workspace/.pythonlibs/lib/python3.11/site-packages/telegram/_bot.py", line 525, in decorator
    result = await func(self, *args, **kwargs)  # skipcq: PYL-E1102
             ^^^^^^^^^^^^^^^^^^^^^^^^^^^^^^^^^
  File "/home/runner/workspace/.pythonlibs/lib/python3.11/site-packages/telegram/_bot.py", line 3584, in get_updates
    await self._post(
  File "/home/runner/workspace/.pythonlibs/lib/python3.11/site-packages/telegram/_bot.py", line 613, in _post
    return await self._do_post(
           ^^^^^^^^^^^^^^^^^^^^
  File "/home/runner/workspace/.pythonlibs/lib/python3.11/site-packages/telegram/ext/_extbot.py", line 340, in _do_post
    return await super()._do_post(
           ^^^^^^^^^^^^^^^^^^^^^^^
  File "/home/runner/workspace/.pythonlibs/lib/python3.11/site-packages/telegram/_bot.py", line 641, in _do_post
    return await request.post(
           ^^^^^^^^^^^^^^^^^^^
  File "/home/runner/workspace/.pythonlibs/lib/python3.11/site-packages/telegram/request/_baserequest.py", line 200, in post
    result = await self._request_wrapper(
             ^^^^^^^^^^^^^^^^^^^^^^^^^^^^
  File "/home/runner/workspace/.pythonlibs/lib/python3.11/site-packages/telegram/request/_baserequest.py", line 381, in _request_wrapper
    raise Conflict(message)
telegram.error.Conflict: Conflict: terminated by other getUpdates request; make sure that only one bot instance is running
2025-09-16 11:37:35,395 - httpx - INFO - HTTP Request: POST https://api.telegram.org/bot8025028159:AAGcBBSs46xwjxEwEU3hYWZx-xE98tUXd0c/getUpdates "HTTP/1.1 409 Conflict"
2025-09-16 11:37:35,395 - telegram.ext.Updater - ERROR - Error while getting Updates: Conflict: terminated by other getUpdates request; make sure that only one bot instance is running
2025-09-16 11:37:35,395 - telegram.ext.Application - ERROR - No error handlers are registered, logging exception.
Traceback (most recent call last):
  File "/home/runner/workspace/.pythonlibs/lib/python3.11/site-packages/telegram/ext/_updater.py", line 688, in _network_loop_retry
    if not await action_cb():
           ^^^^^^^^^^^^^^^^^
  File "/home/runner/workspace/.pythonlibs/lib/python3.11/site-packages/telegram/ext/_updater.py", line 384, in polling_action_cb
    raise exc
  File "/home/runner/workspace/.pythonlibs/lib/python3.11/site-packages/telegram/ext/_updater.py", line 373, in polling_action_cb
    updates = await self.bot.get_updates(
              ^^^^^^^^^^^^^^^^^^^^^^^^^^^
  File "/home/runner/workspace/.pythonlibs/lib/python3.11/site-packages/telegram/ext/_extbot.py", line 558, in get_updates
    updates = await super().get_updates(
              ^^^^^^^^^^^^^^^^^^^^^^^^^^
  File "/home/runner/workspace/.pythonlibs/lib/python3.11/site-packages/telegram/_bot.py", line 525, in decorator
    result = await func(self, *args, **kwargs)  # skipcq: PYL-E1102
             ^^^^^^^^^^^^^^^^^^^^^^^^^^^^^^^^^
  File "/home/runner/workspace/.pythonlibs/lib/python3.11/site-packages/telegram/_bot.py", line 3584, in get_updates
    await self._post(
  File "/home/runner/workspace/.pythonlibs/lib/python3.11/site-packages/telegram/_bot.py", line 613, in _post
    return await self._do_post(
           ^^^^^^^^^^^^^^^^^^^^
  File "/home/runner/workspace/.pythonlibs/lib/python3.11/site-packages/telegram/ext/_extbot.py", line 340, in _do_post
    return await super()._do_post(
           ^^^^^^^^^^^^^^^^^^^^^^^
  File "/home/runner/workspace/.pythonlibs/lib/python3.11/site-packages/telegram/_bot.py", line 641, in _do_post
    return await request.post(
           ^^^^^^^^^^^^^^^^^^^
  File "/home/runner/workspace/.pythonlibs/lib/python3.11/site-packages/telegram/request/_baserequest.py", line 200, in post
    result = await self._request_wrapper(
             ^^^^^^^^^^^^^^^^^^^^^^^^^^^^
  File "/home/runner/workspace/.pythonlibs/lib/python3.11/site-packages/telegram/request/_baserequest.py", line 381, in _request_wrapper
    raise Conflict(message)
telegram.error.Conflict: Conflict: terminated by other getUpdates request; make sure that only one bot instance is running
